<?xml version="1.0"?>
<robot name="project" xmlns:xacro="http://ros.org/wiki/xacro">

  <material name="blue">
    <color rgba="0 0 0.8 0.5"/>
  </material>
  <material name="black">
    <color rgba="0 0 0 0.5"/>
  </material>
    <material name="red">
    <color rgba="1 0 0 0.5"/>
  </material>

  
  <xacro:macro name="default_inertial" params="mass">
    <inertial>
      <mass value="${mass}" />
      <inertia ixx="1.0" ixy="0.0" ixz="0.0" iyy="1.0" iyz="0.0" izz="1.0" />
    </inertial>
   </xacro:macro>
   
     <link name="base_link">
    <visual>
      <geometry>
        <mesh filename="package://urdf_project/meshes/Robot Body.stl"  scale="0.01 0.01 0.01" />
      </geometry>
      <material name="blue"/>
    </visual>
    <collision>
      <geometry>
       <mesh filename="package://urdf_project/meshes/Robot Body.stl"  scale="0.01 0.01 0.01" />
      </geometry>    
    </collision>
<xacro:default_inertial mass="10"/>
  </link>
  

  
  
    <xacro:macro name="wheel" params="prefix suffix left back">
    <link name="${prefix}_${suffix}_wheel">
   <visual>
    <origin rpy="0 1.57075 0" xyz="0 0 0"/>
      <geometry>
         <cylinder length="0.24" radius="0.26"/>
      </geometry>
            <material name="black"/>
    </visual>
    <collision>
    <origin rpy="0 1.57075 0" xyz="0 0 0"/>
      <geometry>
        <cylinder length="0.24" radius="0.26"/>
      </geometry>    
    </collision>
    <xacro:default_inertial mass="1"/>
      </link>
    
    <joint name="${prefix}_${suffix}_wheel_joint" type="continuous">
    <origin xyz="${0.52*left} ${0.45*back} 0.05"/>
    <parent link="base_link"/>
    <child link="${prefix}_${suffix}_wheel"/>
    <axis xyz="1 0 0"/>
  </joint>
  
<gazebo reference="${prefix}_${suffix}_wheel">
      <mu1 value="200.0"/>
      <mu2 value="100.0"/>
      <kp value="10000000.0" />
      <kd value="1.0" />
      <material>Gazebo/Grey</material>
    </gazebo>

    <!-- This block connects the wheel joint to an actuator (motor), which informs both
    simulation and visualization of the robot -->
    <transmission name="${prefix}_${suffix}_wheel_trans">
      <type>transmission_interface/SimpleTransmission</type>
      <actuator name="${prefix}_${suffix}_wheel_motor">
        <mechanicalReduction>1</mechanicalReduction>
      </actuator>
      <joint name="${prefix}_${suffix}_wheel_joint">
        <hardwareInterface>VelocityJointInterface</hardwareInterface>
      </joint>
    </transmission>  
   </xacro:macro>
  
 <xacro:wheel prefix = 'front' suffix ='left' left='1' back='-1' />
 <xacro:wheel prefix = 'front' suffix ='right' left='-1' back='-1' />
 <xacro:wheel prefix = 'rear' suffix ='left' left='1' back='1' />
 <xacro:wheel prefix = 'rear' suffix ='right' left='-1' back='1' />
  
  <link name="sensor">
    <visual>
      <geometry>
        <mesh filename="package://urdf_project/meshes/Lidar Sensor.stl"  scale="0.01 0.01 0.01" />
      </geometry>
      <material name="red"/>
    </visual>
    <collision>
      <geometry>
       <mesh filename="package://urdf_project/meshes/Lidar Sensor.stl"  scale="0.01 0.01 0.01" />
      </geometry>    
    </collision>
<xacro:default_inertial mass="1"/>
  </link>
  
    <joint name="sensor_joint" type="fixed">
    <origin xyz="0 0 0.6"/>
    <parent link="base_link"/>
    <child link="sensor"/>
  </joint>
  
  
<gazebo>
<plugin name="gazebo_ros_control"
filename="libgazebo_ros_control.so">
<robotNamespace>/</robotNamespace>
</plugin>
</gazebo>
  

  
   </robot>
   
  
